Workbook

Sheet Drivers, Inputs and Outputs
B1: Drivers and Inputs
B2: All figures in USD millions unless stated | E2: 44592 | F2: =EDATE(E2,12) -> 44957 | G2: =EDATE(F2,12) -> 45322 | H2: =EDATE(G2,12) -> 45688 | I2: =EDATE(H2,12) -> 46053 | J2: =EDATE(I2,12) -> 46418 | K2: =EDATE(J2,12) -> 46783 | L2: =EDATE(K2,12) -> 47149 | M2: =EDATE(L2,12) -> 47514 | N2: =EDATE(M2,12) -> 47879 | O2: Term
B4: Growth Rate | J4: 0.05 | K4: 0.0525 | L4: 0.0525 | M4: 0.055 | N4: 0.0575 | O4: 0.06 | Q4: Aggregate Growth rate taken from Earnings report and previous trend
B6: Cost of Sales | J6: 0.75 | K6: 0.7495 | L6: 0.749 | M6: 0.7485 | N6: 0.748 | O6: 0.7475 | Q6: Assumed to reduce to match with historical years and might increase during distress times like in 2023 cause of Russia - Ukraine conflict
B8: SG&A | J8: 0.205 | K8: 0.2045 | L8: 0.204 | M8: 0.2035 | N8: 0.203 | O8: 0.2025 | Q8: Assumed to reduce slowly in line with historicals as previous years registers similar figures in range of 20%
B10: CapEx | J10: =Model!K7*Model!K584 -> 28119.832 | K10: =Model!L7*Model!L584 -> 31616.838 | L10: =Model!M7*Model!M584 -> 33330.972 | M10: =Model!N7*Model!N584 -> 37427.195 | N10: =Model!O7*Model!O584 -> 39652.939 | O10: =Model!P7*Model!P584 -> 0 | Q10: Assumes only 3.5% of Rev to closely match with the historicals
B12: Accounts Recievables Days | J12: 5.6 | K12: 5.5 | L12: 5.4 | M12: 5.3 | N12: 5.2 | O12: 5.1 | Q12: Assuming that AR days might improve gradually towards 5 days
B13: Invetory Days | J13: 40 | K13: 39.5 | L13: 39 | M13: 38.5 | N13: 38 | O13: 37.5 | Q13: Assuming that Inventory days will improve matching the trend and might hover around 38 in the future but shown will improve matching the trend
B14: Accounts Payable Days | J14: 42.25 | K14: 42.5 | L14: 42.5 | M14: 42.75 | N14: 43 | O14: 43.25 | Q14: Assumed to improve again as it fluctuates between 42 to 43
B18: Taxes | J18: Assets & Depreciation
B20: Tax Rate | G20: 0.245 | J20: First Year Accounting Depreciation/ Depreciable First year Amount | O20: 0.5 | Q20: Tax rate is in the range 24% to 25% as mentioned in the report
B21: First Year Tax Depreciation | G21: 0.3 | J21: Usefull life: Existing assets | O21: 15 | Q21: Tax Basis for assets is calculated using (
B22: Blended tax Depreciation Rate | G22: 0.15 | J22: Usefull life: New assets | O22: 12
B23: Tax basis for Assets | G23: =(Model!J270-(Notes!G28/'Drivers, Inputs and Outputs'!G20)) -> 111095.24 | H23: end of 2026 | Q23: For Tax Basis for assets is calculated using the formula (net ppe- (DTL ppe/tax rate))basically back solving the using formula used to claculate the DTL
B24: Tax Losses | G24: 0 | H24: end of 2026 | J24: Net PP&E at the End of 2026FY | O24: =Notes!G11 -> 136083 | Q24: NO Tax losses as Walmart been genrating good taxable income meaning they are profitable assuming zero for tax losses.
J25: Gross PP&E at the End of 2026FY | O25: =Notes!G9 -> 256421
J26: Depreciable Assets | O26: 216939
B28: Interest Rates | J28: Leases
B30: Cash Balances | G30: 0.02 | J30: Op Lease Weighted Avg Discount Rate | O30: 0.067 | Q30: Assumed to be Constant at 2026FY Discount Rate
B31: Revolving Credit Line | G31: 0.0475 | J31: Finance Weighted Avg Discount Rate | O31: 0.07
B32: Long Term Debt | G32: 0.05
B33: Short term Debt | G33: 0.0425 | J33: New Op Leases | O33: 2303 | Q33: New leases (OP and Finance) as on 2026FY and assumed to grow each year by 3.5% pa from 2027FY
J34: New Finance Lease | O34: 703
B35: Dates
J36: Other Single Inputs
B37: Valuation Date | G37: 46174
B38: First Expected Cash Flow | G38: 46234 | J38: Dividend Payout ratio | O38: 0.34
B39: First Fiscal Year End for Forecast | G39: 46418 | J39: NCI Dividend/Distribution | O39: 0.5
B40: First Year of Forecast | G40: 2026 | J40: Total Debt | O40: =Model!J95+Model!J101+Model!J103 -> 51523
B41: Incorrect Date Set for Valuation? | G41: =IF(G37>G38,1,0) -> 0 | J41: Cash | O41: =Model!J81 -> 10727
B42: Incorrect Date Set for First Cash Flow? | G42: =IF(G38>G39,1,0) -> 0 | J42: Market Capitalization | O42: 797240.25
B43: Days in Period | G43: 365
B48: Weighted Average Cost of Capital
K50: Average | L50: Debt/ | M50: Debt/ | N50: Levered | O50: Unlevered
B51: Name | E51: Exchange | F51: Ticker | G51: Region | I51: Debt | J51: Equity | K51: Tax Rate 1 | L51: Equity | M51: Capital | N51: Beta 2 | O51: Beta 3
B53: Costco Wholesale | E53: NYSE | F53: COST | G53: US | I53: 8132 | J53: 445290 | K53: 0.2497 | L53: =I53/J53 -> 0.018262256 | M53: =I53/(I53+J53) -> 0.017934727 | N53: 0.87 | O53: =N53/(1+(1-K53)*L53) -> 0.85824025
B54: Target Corporation | E54: NYSE | F54: TGT | G54: US | I54: 19420 | J54: 66150 | K54: 0.221 | L54: =I54/J54 -> 0.29357521 | M54: =I54/(I54+J54) -> 0.2269487 | N54: 1.01 | O54: =N54/(1+(1-K54)*L54) -> 0.82201029
B55: The Kroger Co | E55: NYSE | F55: KR | G55: US | I55: 24692 | J55: 39800 | K55: 0.235 | L55: =I55/J55 -> 0.62040201 | M55: =I55/(I55+J55) -> 0.38286919 | N55: 0.42 | O55: =N55/(1+(1-K55)*L55) -> 0.28482155
B56: Amazon.com Inc | E56: NASDAQ | F56: AMZN | G56: US | I56: 138500 | J56: 2500000 | K56: 0.195 | L56: =I56/J56 -> 0.0554 | M56: =I56/(I56+J56) -> 0.052491946 | Q56: Excluded to capture the grocery focused business to calculate the WACC
Q57: As Wlamart is transitioning into more like Amazon but retail at its core
...

Sheet Model
B1: Income Statement | R1: Notes Col
B2: All figures in million $
F3: 44592 | G3: =EDATE(F3,12) -> 44957 | H3: =EDATE(G3,12) -> 45322 | I3: =EDATE(H3,12) -> 45688 | J3: =EDATE(I3,12) -> 46053 | K3: =EDATE(J3,12) -> 46418 | L3: =EDATE(K3,12) -> 46783 | M3: =EDATE(L3,12) -> 47149 | N3: =EDATE(M3,12) -> 47514 | O3: =EDATE(N3,12) -> 47879 | P3: Term
B5: Net sales | F5: 567762 | G5: 605881 | H5: 642637 | I5: 674538 | J5: 706413 | K5: =K162 -> 742757.8 | L5: =L162 -> 782925.83 | M5: =M162 -> 825366.96 | N5: =N162 -> 872277.87 | O5: =O162 -> 924146.59 | P5: =P162 -> 981526.54
B6: Membership and Other Income | F6: 4992 | G6: 5408 | H6: 5488 | I6: 6447 | J6: 6750 | K6: =K163 -> 7104.375 | L6: =L163 -> 7495.1156 | M6: =M163 -> 7907.347 | N6: =N163 -> 8362.0194 | O6: =O163 -> 8863.7406 | P6: =P163 -> 9417.7244
B7: Total Revenue | F7: 572754 | G7: 611289 | H7: 648125 | I7: 680985 | J7: 713163 | K7: =SUM(K5:K6) -> 749862.18 | L7: =SUM(L5:L6) -> 790420.95 | M7: =SUM(M5:M6) -> 833274.3 | N7: =SUM(N5:N6) -> 880639.89 | O7: =SUM(O5:O6) -> 933010.33 | P7: =SUM(P5:P6) -> 990944.27
B9: Cost of Sales | F9: -429000 | G9: -463721 | H9: -490142 | I9: -511753 | J9: -535395 | K9: =K182*-1 -> -562396.63 | L9: =L182*-1 -> -592420.5 | M9: =M182*-1 -> -624122.45 | N9: =N182*-1 -> -659158.96 | O9: =O182*-1 -> -697891.73 | P9: =P182*-1 -> -740730.84
B10: SG&A | F10: -117812 | G10: -127140 | H10: -130971 | I10: -139884 | J10: -147943 | K10: =K183*-1 -> -153721.75 | L10: =L183*-1 -> -161641.08 | M10: =M183*-1 -> -169987.96 | N10: =N183*-1 -> -179210.22 | O10: =O183*-1 -> -189401.1 | P10: =P183*-1 -> -200666.21
B11: Operating Income | F11: 25942 | G11: 20428 | H11: 27012 | I11: 29348 | J11: 29825 | K11: =K7+K9+K10 -> 33743.798 | L11: =L7+L9+L10 -> 36359.364 | M11: =M7+M9+M10 -> 39163.892 | N11: =N7+N9+N10 -> 42270.715 | O11: =O7+O9+O10 -> 45717.506 | P11: =P7+P9+P10 -> 49547.213
B13: Interest Expense, Debt | F13: -16742 | G13: -1787 | H13: -2259 | I13: -2249 | J13: -2318 | K13: =K427 -> -2210.7675 | L13: =L427 -> -2253.1363 | M13: =M427 -> -2294.5487 | N13: =N427 -> -2329.1238 | O13: =O427 -> -2358.7675 | P13: =P427 -> -2375.0175
B14: Interest Expense, Financial lease | F14: -320 | G14: -341 | H14: -424 | I14: -479 | J14: -481 | K14: =K428*-1*-1 -> -473.27 | L14: =L428*-1*-1 -> -493.71385 | M14: =M428*-1*-1 -> -516.64628 | N14: =N428*-1*-1 -> -543.06443 | O14: =O428*-1*-1 -> -574.46582 | P14: =P428*-1*-1 -> 0
B15: Interest Income | F15: 158 | G15: 254 | H15: 546 | I15: 483 | J15: 368 | K15: =K429 -> 198.64009 | L15: =L429 -> 226.92026 | M15: =M429 -> 265.48972 | N15: =N429 -> 305.70289 | O15: =O429 -> 519.16736 | P15: =P429 -> 519.16736
B16: Net Interest | F16: -1836 | G16: -1874 | H16: -2137 | I16: -2245 | J16: -2431 | K16: =SUM(K13:K15) -> -2485.3974 | L16: =SUM(L13:L15) -> -2519.9298 | M16: =SUM(M13:M15) -> -2545.7053 | N16: =SUM(N13:N15) -> -2566.4853 | O16: =SUM(O13:O15) -> -2414.066 | P16: =SUM(P13:P15) -> -1855.8501
B17: loss on estinguishment of debt | F17: -2410 | G17: 0 | H17: 0 | I17: 0 | J17: 0 | K17: 0 | L17: 0 | M17: 0 | N17: 0 | O17: 0 | P17: 0
B19: Other gains/ (losses) | F19: -3000 | G19: -1538 | H19: -3027 | I19: -794 | J19: 2075 | K19: =K548 -> 0 | L19: =L548 -> 0 | M19: =M548 -> 0 | N19: =N548 -> 0 | O19: =O548 -> 0 | P19: =P548 -> 0 | R19: might consider an average value but for now its 0
B20: Income before Income taxes | F20: 18696 | G20: 17016 | H20: 21848 | I20: 26309 | J20: 29469 | K20: =K11+K16+K17+K19 -> 31258.401 | L20: =L11+L16+L17+L19 -> 33839.434 | M20: =M11+M16+M17+M19 -> 36618.187 | N20: =N11+N16+N17+N19 -> 39704.229 | O20: =O11+O16+O17+O19 -> 43303.44 | P20: =P11+P16+P17+P19 -> 47691.363
B22: Taxes | F22: -4756 | G22: -5724 | H22: -5578 | I22: -6152 | J22: -7199 | K22: =K322*-1 -> -7658.3081 | L22: =L322*-1 -> -8290.6613 | M22: =M322*-1 -> -8971.4558 | N22: =N322*-1 -> -9727.5362 | O22: =O322*-1 -> -10609.343 | P22: =P20*'Drivers, Inputs and Outputs'!G20*-1 -> -11684.384
B23: Net Income | F23: 13940 | G23: 11292 | H23: 16270 | I23: 20157 | J23: 22270 | K23: =K20+K22 -> 23600.092 | L23: =L20+L22 -> 25548.773 | M23: =M20+M22 -> 27646.731 | N23: =N20+N22 -> 29976.693 | O23: =O20+O22 -> 32694.097 | P23: =P20+P22 -> 36006.979
B25: Net Income to Controlling Interest | F25: -267 | G25: 388 | H25: -759 | I25: -721 | J25: -377 | K25: =K550 -> -347.2 | L25: =L550 -> -363.24 | M25: =M550 -> -513.488 | N25: =N550 -> -464.3856 | O25: =O550 -> -413.06272 | P25: =P550 -> 0
B26: Net income to parent | F26: 13673 | G26: 11680 | H26: 15511 | I26: 19436 | J26: 21893 | K26: =K23+K25 -> 23252.892 | L26: =L23+L25 -> 25185.533 | M26: =M23+M25 -> 27133.243 | N26: =N23+N25 -> 29512.308 | O26: =O23+O25 -> 32281.035 | P26: =P23+P25 -> 36006.979
B29: Cash flow Statement
B30: All figures in million $
F31: =F3 -> 44592 | G31: =G3 -> 44957 | H31: =H3 -> 45322 | I31: =I3 -> 45688 | J31: =J3 -> 46053 | K31: =K3 -> 46418 | L31: =L3 -> 46783 | M31: =M3 -> 47149 | ... O31: =O3 -> 47879
B33: Consolidated Net Income | F33: 13940 | G33: 11292 | H33: 16270 | I33: 20157 | J33: 22270 | K33: =K26 -> 23252.892 | L33: =L26 -> 25185.533 | M33: =M26 -> 27133.243 | N33: =N26 -> 29512.308 | O33: =O26 -> 32281.035
B34: (+) D&A | F34: 10658 | G34: 10945 | H34: 11853 | I34: 12973 | J34: 14203 | K34: =K245 -> 15634.26 | L34: =L245 -> 18123.288 | M34: =M245 -> 20829.446 | N34: =N245 -> 23777.703 | O34: =O245 -> 26989.376
B35: (+/-) Investment (gains) and losses | F35: -2440 | G35: -1683 | H35: -3193 | I35: -878 | J35: 2016 | K35: 0 | L35: 0 | M35: 0 | N35: 0 | O35: 0
B36: (+/-) losses on Disposal of business ops | F36: 433 | G36: 0 | H36: 0 | I36: 0 | J36: 0 | K36: 0 | L36: 0 | M36: 0 | N36: 0 | O36: 0
B37: (+/-) Deferred Tax | F37: -755 | G37: 449 | H37: -175 | I37: -635 | J37: 2277 | K37: =K321 -> 2095.5285 | L37: =L321 -> 1738.3776 | M37: =M321 -> 1418.2746 | N37: =N321 -> 1095.1217 | O37: =O321 -> 796.23428
B38: (+/-) Loss on Extinguishment of debt | F38: 2410 | G38: 0 | H38: 0 | I38: 0 | J38: 0 | K38: 0 | L38: 0 | M38: 0 | N38: 0 | O38: 0
B39: (+/-) Other Operating items | F39: 1652 | G39: 1919 | H39: 2642 | I39: 2889 | J39: 4079 | K39: =K594 -> 4424.1868 | L39: =L594 -> 5058.6941 | M39: =M594 -> 5749.5927 | N39: =N594 -> 6516.7352 | O39: =O594 -> 7370.7816
B40: (+/-) Change in Receivables, net | F40: -1796 | G40: 240 | H40: -797 | I40: -1106 | J40: -1136 | K40: =K206 -> -332.73478 | L40: =L206 -> -405.71789 | M40: =M206 -> -417.44113 | N40: =N206 -> -459.47994 | O40: =O206 -> -504.82825
B41: (+/-) Change in Inventories | F41: -11764 | G41: -528 | H41: 2017 | I41: -2755 | J41: -1443 | K41: =K207 -> -2781.5077 | L41: =L207 -> -2478.7521 | M41: =M207 -> -2575.7968 | N41: =N207 -> -2840.669 | O41: =O207 -> -3129.4954
B42: (+/-) Change in Accounts Payable | F42: 5520 | G42: -1425 | H42: 2515 | I42: 3228 | J42: 1611 | K42: =K208 -> 2038.3363 | L42: =L208 -> 3881.1331 | M42: =M208 -> 3691.3231 | N42: =N208 -> 4531.0717 | O42: =O208 -> 5014.5175
B43: (+/-) Change in Prepaid Expenses | G43: =F84-G84 -> -1002 | H43: =G84-H84 -> -801 | I43: =H84-I84 -> -689 | J43: =I84-J84 -> -113 | K43: =J84-K84 -> -241.63596 | L43: =K84-L84 -> -506.82195 | M43: =L84-M84 -> -435.38525 | N43: =M84-N84 -> -603.3013 | O43: =N84-O84 -> -926.67098
B44: (+/-) Change in Other assets | G44: =F91-G91 -> 2018 | H44: =G91-H91 -> 3063 | I44: =H91-I91 -> 4202 | J44: =I91-J91 -> -1234 | K44: =J91-K91 -> -1269.1746 | L44: =K91-L91 -> -1226.6653 | M44: =L91-M91 -> -1316.5576 | N44: =M91-N91 -> -1458.6801 | O44: =N91-O91 -> -1618.6549
B45: (+/-) Accrued Liabilities | F45: 1404 | G45: 4393 | H45: -1324 | I45: 379 | J45: 1607 | K45: =K97-J97 -> 1409.058 | L45: =L97-K97 -> 1568.4783 | M45: =M97-L97 -> 1648.2687 | N45: =N97-M97 -> 1821.3154 | O45: =O97-N97 -> 2012.187
B46: (+/-) Accrued Income Taxes | F46: 39 | G46: -127 | H46: -468 | I46: 435 | J46: 113 | K46: =K98-J98 -> 93.247733 | L46: =L98-K98 -> 56.911784 | M46: =M98-L98 -> 83.700145 | N46: =N98-M98 -> 69.937438 | O46: =O98-N98 -> 108.09047
B47: Cash Flow from Operations | F47: 24181 | G47: 28841 | H47: 35726 | I47: 36443 | J47: 41565 | K47: =SUM(K33:K46) -> 44322.456 | L47: =SUM(L33:L46) -> 50994.458 | M47: =SUM(M33:M46) -> 55808.668 | N47: =SUM(N33:N46) -> 61962.062 | O47: =SUM(O33:O46) -> 68392.572
B49: (-) Net CapEx | F49: -13106 | G49: -16857 | H49: -20606 | I49: -23783 | J49: -26642 | K49: =K257*-1 -> -28119.832 | L49: =L257*-1 -> -31616.838 | M49: =M257*-1 -> -33330.972 | N49: =N257*-1 -> -37427.195 | O49: =O257*-1 -> -39652.939
B50: (+) Disposal Proceeds of PP&E | F50: 394 | G50: 170 | H50: 250 | I50: 432 | J50: 106 | K50: =K576 -> 309.31815 | L50: =L576 -> 363.59364 | M50: =M576 -> 399.97167 | N50: =N576 -> 467.83994 | O50: =O576 -> 515.48821
...

Sheet Notes
A1: Property and Equipment
B2: Estimated useful years
B3: (in years) | C3: 44592 | D3: 44957 | E3: 45322 | F3: 45688 | G3: 46053
A4: Land | B4: N/A | C4: 19204 | D4: 19317 | E4: 19562 | F4: 19342 | G4: 20754
A5: Buildings and improvements | B5: 3 to 40 | C5: 100376 | D5: 104554 | E5: 111767 | F5: 117973 | G5: 128472
A6: Fixtures and Equipments | B6: 2 to 30 | C6: 60282 | D6: 65235 | E6: 72161 | F6: 76226 | G6: 85539 | I6: =231617-19342-15403 -> 196872
A7: Transportation equipment | B7: 3 to 15 | C7: 2263 | D7: 2462 | E7: 2979 | F7: 2673 | G7: 2928
A8: Construction in progress | B8: N/A | C8: 7199 | D8: 10802 | E8: 13390 | F8: 15403 | G8: 18728 | I8: =G9-G4-G8 -> 216939
A9: PP&E | C9: 189324 | D9: 202370 | E9: 219859 | F9: 231617 | G9: 256421
A10: Accumulated depreciation | C10: -94809 | D10: -101610 | E10: -109049 | F10: -111624 | G10: -120338
A11: PPE&E, net | C11: 94515 | D11: 100760 | E11: 110810 | F11: 119993 | G11: 136083 | I11: =G11-G4-G8 -> 96601 | J11: =I11-(G28/24.5%) -> 71613.245
A15: Deferred Taxes
C16: 2022 | D16: 2023 | E16: 2024 | F16: 2025 | G16: 2026
A17: (Amounts in millions)
A18: Deferred tax assets:
A19: Loss and tax credit carryforwards | C19: 9456 | D19: 7690 | E19: 7136 | F19: 7539 | G19: 4615
A20: Accrued liabilities | C20: 2752 | D20: 3312 | E20: 3066 | F20: 3009 | G20: 3504
A21: Share-based compensation | C21: 231 | D21: 237 | E21: 238 | F21: 263 | G21: 0
A22: Lease obligations | C22: 4320 | D22: 4653 | E22: 4831 | F22: 4611 | G22: 5181
A23: Other | C23: 893 | D23: 839 | E23: 1124 | F23: 1076 | G23: 1239 | H23: In 2026 the other line itme here may contain share based compensation as it is omitted form th eactual notes for 2026 report.
A24: Total deferred tax assets | C24: 17652 | D24: 16731 | E24: 16395 | F24: 16498 | G24: 14539
A25: Valuation allowances | C25: -9542 | D25: -7815 | E25: -7485 | F25: -7405 | G25: -4421
A26: Deferred tax assets, net of valuation allowances | C26: 8110 | D26: 8916 | E26: 8910 | F26: 9093 | G26: 10118
A27: Deferred tax liabilities:
A28: Property and equipment | C28: 4414 | D28: 4352 | E28: 4813 | F28: 4303 | G28: 6122
A29: Acquired intangibles | C29: 1065 | D29: 932 | E29: 898 | F29: 1096 | G29: 1066
A30: Inventory | C30: 1588 | D30: 3032 | E30: 3035 | F30: 3336 | G30: 3570
A31: Lease right of use assets | C31: 4355 | D31: 4727 | E31: 4941 | F31: 4816 | G31: 5345
A32: Mark-to-market investments | C32: 1825 | D32: 1390 | E32: 322 | F32: 353 | G32: 0 | H32: Same as Share based Compensation, Mark to Market is clubbed with the other making others 460 to 813 in value
A33: Other | C33: 307 | D33: 249 | E33: 486 | F33: 460 | G33: 1373
A34: Total deferred tax liabilities | C34: 13554 | D34: 14682 | E34: 14495 | F34: 14364 | G34: 17476
A35: Net deferred tax liabilities | C35: 5444 | D35: 5766 | E35: 5585 | F35: 5271 | G35: 7358
A38: Short Term Borrowings and Long Term Debt
A40: Short-term borrowings consist of commercial paper and lines of credit.
A41: Short-term borrowings as of January 31, 2025 and 2024 were $3.1 billion and $0.9 billion, respectively, with weighted-average interest rates of 5.3% and 7.7%, respectively.
A42: Short-term borrowings as of January 31, 2026 and 2025 were $6.6 billion and $3.1 billion, respectively, with weighted-average interest rates of 4% and 5.3%, respectively.
A43: committed line of credit in US to support Commercial Paper program | D43: Jan 31st 2024 | G43: Jan 31st 2025
D44: Available | E44: drawn | F44: Undrawn | G44: Available | H44: drawn | I44: Undrawn | J44: same with 2026 year as the 2025 year
A45: Five year credit facility | D45: 5000 | E45: 0 | F45: 5000 | G45: 5000 | H45: 0 | I45: 5000 | J45: same balaces foe 2023, 2022
A46: 364- days revolving credit facility | D46: 10000 | E46: 0 | F46: 10000 | G46: 10000 | H46: 0 | I46: 10000
...
